<?xml version="1.0"?>
<robot name="C:/Users/morga/OneDrive/Documents/Webots_FYP/Robot.urdf" xmlns:xacro="http://ros.org/wiki/xacro">
  <link name="base_link">
  </link>
  <joint name="torso_1" type="revolute">
    <parent link="base_link"/>
    <child link="torso"/>
    <axis xyz="1 0 0"/>
    <limit effort="36" lower="-0.2618" upper="1.5708" velocity="10"/>
    <origin xyz="0 0 -0.08" rpy="0 0 0"/>
  </joint>
  <link name="torso">
  </link>
  <joint name="torso_2" type="revolute">
    <parent link="torso"/>
    <child link="solid"/>
    <axis xyz="0 0 1"/>
    <limit effort="50" lower="-1.2217" upper="1.2217" velocity="10"/>
    <origin xyz="0 0 -0.025" rpy="0 0 0"/>
  </joint>
  <link name="solid">
  </link>
  <joint name="torso_3" type="revolute">
    <parent link="solid"/>
    <child link="solid_0"/>
    <axis xyz="-1 0 0"/>
    <limit effort="50" lower="-0.7854" upper="0.7854" velocity="10"/>
    <origin xyz="-0.01 0 0" rpy="0 0 0"/>
  </joint>
  <link name="solid_8">
    <visual>
      <origin xyz="0.05 0 -0.02" rpy="0 0 0"/>
      <geometry>
        <box size="0.13 0.05 0.025"/>
      </geometry>
    </visual>
    <collision>
      <origin xyz="0.05 0 -0.02" rpy="0 0 0"/>
      <geometry>
        <box size="0.13 0.05 0.025"/>
      </geometry>
    </collision>
  </link>
  <joint name="left_arm_1" type="revolute">
    <parent link="base_link"/>
    <child link="left_arm"/>
    <axis xyz="1 0 0"/>
    <limit effort="34" lower="-0.8727" upper="4.0143" velocity="10"/>
    <origin xyz="-0.01 0.093 0.02" rpy="-0.000001 0 0"/>
  </joint>
  <link name="left_arm">
  </link>
  <joint name="left_arm_2" type="revolute">
    <parent link="left_arm"/>
    <child link="solid_9"/>
    <axis xyz="-1 0 0"/>
    <limit effort="40" lower="-2.618" upper="1.5708" velocity="10"/>
    <origin xyz="0 0.01 0" rpy="0.1 0 0"/>
  </joint>
  <link name="solid_9">
  </link>
  <joint name="left_arm_3" type="revolute">
    <parent link="solid_9"/>
    <child link="solid_10"/>
    <axis xyz="0 0 1"/>
    <limit effort="34" lower="-1.5708" upper="1.5708" velocity="10"/>
    <origin xyz="0 0.005 -0.01" rpy="0 0 0"/>
  </joint>
  <link name="solid_10">
    <visual>
      <origin xyz="0 0 -0.07" rpy="0 0 0"/>
      <geometry>
        <cylinder radius="0.019" length="0.14"/>
      </geometry>
    </visual>
    <collision>
      <origin xyz="0 0 -0.07" rpy="0 0 0"/>
      <geometry>
        <cylinder radius="0.019" length="0.14"/>
      </geometry>
    </collision>
  </link>
  <joint name="left_elbow" type="revolute">
    <parent link="solid_10"/>
    <child link="solid_11"/>
    <axis xyz="1 0 0"/>
    <limit effort="20" lower="-3.41939e-07" upper="2.4435" velocity="10"/>
    <origin xyz="0 0 -0.14" rpy="0 0 0"/>
  </joint>
  <link name="solid_11">
    <visual>
      <origin xyz="0 0 -0.07" rpy="0 0 0"/>
      <geometry>
        <cylinder radius="0.015" length="0.122"/>
      </geometry>
    </visual>
    <collision>
      <origin xyz="0 0 -0.07" rpy="0 0 0"/>
      <geometry>
        <cylinder radius="0.015" length="0.122"/>
      </geometry>
    </collision>
  </link>
  <joint name="left_forearm" type="revolute">
    <parent link="solid_11"/>
    <child link="solid_12"/>
    <axis xyz="0 0 1"/>
    <limit effort="0.45" lower="-0.5236" upper="0.5236" velocity="10"/>
    <origin xyz="0 0 0.01" rpy="0 0 0"/>
  </joint>
  <link name="solid_12">
    <visual>
      <origin xyz="0 0 -0.07" rpy="0 0 0"/>
      <geometry>
        <cylinder radius="0.015" length="0.122"/>
      </geometry>
    </visual>
    <collision>
      <origin xyz="0 0 -0.07" rpy="0 0 0"/>
      <geometry>
        <cylinder radius="0.015" length="0.122"/>
      </geometry>
    </collision>
  </link>
  <joint name="left_wrist_1" type="revolute">
    <parent link="solid_12"/>
    <child link="solid_13"/>
    <axis xyz="1 0 0"/>
    <limit effort="0.65" lower="-1.5708" upper="1.5708" velocity="10"/>
    <origin xyz="0 0 -0.135" rpy="0 0 0"/>
  </joint>
  <link name="solid_13">
  </link>
  <joint name="left_wrist_2" type="revolute">
    <parent link="solid_13"/>
    <child link="solid_14"/>
    <axis xyz="0 0 1"/>
    <limit effort="0.65" lower="-1.5708" upper="1.5708" velocity="10"/>
    <origin xyz="0 0 0.01" rpy="0 0 0"/>
  </joint>
  <link name="solid_14">
    <visual>
      <origin xyz="0 0 -0.04" rpy="0 0 0"/>
      <geometry>
        <box size="0.05 0.015 0.06"/>
      </geometry>
    </visual>
    <collision>
      <origin xyz="0 0 -0.04" rpy="0 0 0"/>
      <geometry>
        <box size="0.05 0.015 0.06"/>
      </geometry>
    </collision>
  </link>
</robot>
