#VRML_SIM R2023a utf8

EXTERNPROTO "https://raw.githubusercontent.com/cyberbotics/webots/R2023a/projects/objects/backgrounds/protos/TexturedBackground.proto"
EXTERNPROTO "https://raw.githubusercontent.com/cyberbotics/webots/R2023a/projects/objects/backgrounds/protos/TexturedBackgroundLight.proto"
EXTERNPROTO "https://raw.githubusercontent.com/cyberbotics/webots/R2023a/projects/objects/floors/protos/RectangleArena.proto"
EXTERNPROTO "../protos/Ball.proto"

WorldInfo {
}
Viewpoint {
  orientation 0.18036137845653052 -0.056682273279500546 -0.9819658309010189 3.7402382026098016
  position 12.02141525451473 -5.67342095841207 6.226428944901469
}
TexturedBackground {
}
TexturedBackgroundLight {
}
RectangleArena {
  translation 0.26028 0.368433 -8.54872e-15
  floorSize 5 5
}
Robot {
  children [
    Solid {
      children [
        HingeJoint {
          jointParameters HingeJointParameters {
            axis 0 0 1
            anchor -0.5 0 0
          }
          device [
            RotationalMotor {
              name "joint1"
              minPosition -5
              maxPosition 5
            }
          ]
          endPoint Solid {
            children [
              Solid {
                children [
                  Shape {
                    appearance PBRAppearance {
                    }
                    geometry Box {
                      size 1 0.1 0.1
                    }
                  }
                ]
              }
              HingeJoint {
                jointParameters HingeJointParameters {
                  axis 0 0 1
                  anchor 0.5 0 0
                }
                device [
                  RotationalMotor {
                    name "joint2"
                  }
                ]
                endPoint Solid {
                  translation 1 0 0
                  children [
                    Shape {
                      appearance PBRAppearance {
                        metalness 0
                      }
                      geometry Box {
                        size 1 0.1 0.1
                      }
                    }
                  ]
                  name "solid(1)"
                }
              }
            ]
          }
        }
      ]
    }
  ]
  name "2joints"
  controller "PmpMain_2JointsPlanar"
  supervisor TRUE
}
DEF Ball3 Ball {
  translation 1.62494 2.18219 0.03
  name "Ball3"
  color 1 0.2 0
  mass 1
}
DEF Ball Solid {
  translation 1.08294 -0.617229 0.06
  scale 3 3 3
  children [
    Ball {
      color 1 0 0.0156863
      mass -1
    }
  ]
}
Ball {
  translation 0.667903 2.45612 0.02
  name "Ball2"
  mass -1
}
