#VRML_SIM R2023a utf8

EXTERNPROTO "https://raw.githubusercontent.com/cyberbotics/webots/R2023a/projects/objects/backgrounds/protos/TexturedBackground.proto"
EXTERNPROTO "https://raw.githubusercontent.com/cyberbotics/webots/R2023a/projects/objects/backgrounds/protos/TexturedBackgroundLight.proto"
EXTERNPROTO "https://raw.githubusercontent.com/cyberbotics/webots/R2023a/projects/objects/floors/protos/RectangleArena.proto"
EXTERNPROTO "../protos/Ball.proto"

WorldInfo {
}
Viewpoint {
  orientation 0.2577318719536258 -0.08526509717096778 -0.9624469571793061 3.7580926638192675
  position 6.523475759274187 -2.888747920124303 4.731332419579036
}
TexturedBackground {
}
TexturedBackgroundLight {
}
RectangleArena {
  translation 0.26028 0.368433 -8.54872e-15
  floorSize 5 5
}
Robot {
  children [
    Solid {
      children [
        HingeJoint {
          jointParameters HingeJointParameters {
            axis 0 0 1
            anchor -0.25 0 0
          }
          device [
            RotationalMotor {
              name "joint1"
              minPosition -5
              maxPosition 5
            }
          ]
          endPoint Solid {
            children [
              Solid {
                children [
                  Shape {
                    appearance PBRAppearance {
                    }
                    geometry Box {
                      size 0.5 0.1 0.1
                    }
                  }
                ]
              }
              HingeJoint {
                jointParameters HingeJointParameters {
                  axis 0 0 1
                  anchor 0.25 0 0
                }
                device [
                  RotationalMotor {
                    name "joint2"
                  }
                ]
                endPoint Solid {
                  translation 1 0 0
                  children [
                    Shape {
                      appearance PBRAppearance {
                        metalness 0
                      }
                      geometry Box {
                        size 1.5 0.1 0.1
                      }
                    }
                  ]
                  name "solid(1)"
                }
              }
            ]
          }
        }
      ]
    }
  ]
  name "2joints"
  controller "PmpMain_2JointsPlanar2"
  supervisor TRUE
}
DEF Ball Ball {
  translation 0.853669 0.912401 0.03
  name "Ball"
  color 1 0.2 0
  mass 1
}
