#VRML_SIM R2023a utf8

EXTERNPROTO "https://raw.githubusercontent.com/cyberbotics/webots/R2023a/projects/objects/backgrounds/protos/TexturedBackground.proto"
EXTERNPROTO "https://raw.githubusercontent.com/cyberbotics/webots/R2023a/projects/objects/backgrounds/protos/TexturedBackgroundLight.proto"
EXTERNPROTO "https://raw.githubusercontent.com/cyberbotics/webots/R2023a/projects/objects/floors/protos/RectangleArena.proto"

WorldInfo {
}
Viewpoint {
  orientation 0.32582154317694223 -0.11415409674737868 -0.9385143388343015 3.7769424518948007
  position 7.2750633519588455 -6.389844908315618 9.058890907723438
}
TexturedBackground {
}
TexturedBackgroundLight {
}
RectangleArena {
  translation 0.26028 0.368433 -8.54872e-15
  floorSize 5 5
}
DEF Ball Solid {
  translation 1.94595 -0.014473 0.99
  children [
    Shape {
      appearance Appearance {
        material Material {
          emissiveColor 1 1 0.498039
          specularColor 1 0.666667 0
        }
        texture ImageTexture {
        }
      }
      geometry Sphere {
        radius 0.1
      }
      castShadows FALSE
    }
  ]
  name "Ball"
}
DEF MyArm Robot {
  translation -0.160572 1.20316 -8.88178e-16
  children [
    HingeJoint {
      jointParameters HingeJointParameters {
        axis 0 1 0
        anchor 0 0 1
      }
      device [
        RotationalMotor {
          name "joint1"
        }
      ]
      endPoint Solid {
        translation 0 0 1
        rotation 0 1 0 0
        children [
          HingeJoint {
            jointParameters HingeJointParameters {
              axis 0 0 1
            }
            device [
              RotationalMotor {
                name "joint2"
              }
            ]
            endPoint Solid {
              children [
                HingeJoint {
                  jointParameters HingeJointParameters {
                    axis 0 0 1
                    anchor 1 0 0
                  }
                  device [
                    RotationalMotor {
                      name "joint3"
                    }
                  ]
                  endPoint Solid {
                    translation 1 0 0
                    children [
                      DEF link3Shape Transform {
                        translation 0.5 0 0
                        children [
                          Shape {
                            appearance Appearance {
                              material Material {
                                diffuseColor 0.717647 0.105882 0.8
                              }
                            }
                            geometry Box {
                              size 1 0.1 0.1
                            }
                          }
                        ]
                      }
                    ]
                  }
                }
                DEF link2Shape Transform {
                  translation 0.5 0 0
                  children [
                    Shape {
                      appearance Appearance {
                        material Material {
                          diffuseColor 0.0431373 0.509804 0.8
                        }
                      }
                      geometry Box {
                        size 1 0.1 0.1
                      }
                    }
                  ]
                }
              ]
              boundingObject USE link2Shape
            }
          }
        ]
        name "link1"
        boundingObject DEF link1Shape Transform {
          translation 0.5 0 0
        }
      }
    }
    DEF baseObject Transform {
      translation 0 0 0.5
      rotation 0 1 0 0
      children [
        Shape {
          appearance Appearance {
            material Material {
            }
            texture ImageTexture {
            }
          }
          geometry Box {
            size 0.1 0.1 1
          }
        }
      ]
    }
  ]
  name "MyArm"
  boundingObject USE baseObject
  controller "<none>"
}
Robot {
  translation -1.96788 2.1438 -3.55271e-15
  children [
    Solid {
      children [
        HingeJoint {
          jointParameters HingeJointParameters {
            axis 0 0 1
          }
          device [
            RotationalMotor {
              name "joint1"
            }
            PositionSensor {
              name "joint1_PS"
            }
          ]
          endPoint Solid {
            translation 0 0 0.5
            children [
              Shape {
                appearance Appearance {
                  material Material {
                    diffuseColor 0.8 0 0.321569
                  }
                }
                geometry Box {
                  size 0.1 0.1 1
                }
              }
              HingeJoint {
                jointParameters HingeJointParameters {
                  axis 0 1 0
                }
                device [
                  PositionSensor {
                    name "joint2_PS"
                  }
                  RotationalMotor {
                    name "joint2"
                  }
                ]
                endPoint Solid {
                  translation 0.5 0 0.5
                  children [
                    Shape {
                      appearance Appearance {
                        material Material {
                          diffuseColor 0.8 0.321569 0
                        }
                      }
                      geometry Box {
                        size 1 0.1 0.1
                      }
                    }
                    HingeJoint {
                      jointParameters HingeJointParameters {
                        axis 0 1 0
                      }
                      device [
                        PositionSensor {
                          name "joint3_PS"
                        }
                        RotationalMotor {
                          name "joint3"
                        }
                      ]
                      endPoint Solid {
                        translation 1 0 0
                        children [
                          Shape {
                            appearance Appearance {
                              material Material {
                                diffuseColor 0.211765 0.701961 0.8
                              }
                            }
                            geometry Box {
                              size 1 0.1 0.1
                            }
                          }
                        ]
                      }
                    }
                  ]
                }
              }
            ]
          }
        }
      ]
    }
  ]
  name "3Joints3DOF"
  controller "<none>"
}
Robot {
  translation 0.670776 2.07976 0
  children [
    Solid {
      children [
        Transform {
          translation 0 0 0.5
          children [
            Shape {
              appearance Appearance {
                material Material {
                  diffuseColor 0.8 0.266667 0
                }
              }
              geometry Box {
                size 0.1 0.1 1
              }
            }
          ]
        }
        HingeJoint {
          jointParameters HingeJointParameters {
            axis 0 1 0
          }
          device [
            RotationalMotor {
              name "joint1"
            }
          ]
          endPoint Solid {
            rotation 0 1 0 0
            children [
              HingeJoint {
                jointParameters HingeJointParameters {
                  axis 0 0 1
                }
                device [
                  RotationalMotor {
                    name "joint2"
                  }
                ]
                endPoint Solid {
                  children [
                    Transform {
                      translation 0.5 0 1
                      children [
                        Shape {
                          appearance Appearance {
                            material Material {
                              diffuseColor 0.8 0.435294 0.654902
                            }
                          }
                          geometry Box {
                            size 1 0.1 0.1
                          }
                        }
                      ]
                    }
                    HingeJoint {
                      jointParameters HingeJointParameters {
                        axis 0 0 1
                      }
                      device [
                        RotationalMotor {
                          name "joint3"
                        }
                      ]
                      endPoint Solid {
                        children [
                          Transform {
                            translation 1.5 0 1
                            children [
                              Shape {
                                appearance Appearance {
                                  material Material {
                                    diffuseColor 0.0431373 0.184314 0.8
                                  }
                                }
                                geometry Box {
                                  size 1 0.1 0.1
                                }
                              }
                            ]
                          }
                        ]
                      }
                    }
                  ]
                }
              }
            ]
          }
        }
      ]
    }
  ]
  controller "PmpMain_3Joints3DOF"
}
