#VRML_SIM R2023a utf8

EXTERNPROTO "https://raw.githubusercontent.com/cyberbotics/webots/R2023a/projects/objects/backgrounds/protos/TexturedBackground.proto"
EXTERNPROTO "https://raw.githubusercontent.com/cyberbotics/webots/R2023a/projects/objects/backgrounds/protos/TexturedBackgroundLight.proto"
EXTERNPROTO "https://raw.githubusercontent.com/cyberbotics/webots/R2023a/projects/objects/floors/protos/RectangleArena.proto"
EXTERNPROTO "../protos/Ball.proto"

WorldInfo {
}
Viewpoint {
  orientation 0.29116485036675344 -0.0887118538529201 -0.9525509103963338 3.706508027309926
  position 4.162576091146479 -2.094227598807441 3.3157524209415006
}
TexturedBackground {
}
TexturedBackgroundLight {
}
RectangleArena {
  translation 0.26028 0.368433 -8.54872e-15
  floorSize 5 5
}
Robot {
  children [
    Solid {
      children [
        HingeJoint {
          jointParameters HingeJointParameters {
            axis 0 0 1
            anchor -0.5 0 0
          }
          device [
            RotationalMotor {
              name "joint1"
              minPosition -5
              maxPosition 5
            }
          ]
          endPoint Solid {
            children [
              Solid {
                children [
                  Shape {
                    appearance PBRAppearance {
                    }
                    geometry Box {
                      size 1 0.1 0.1
                    }
                  }
                ]
              }
              HingeJoint {
                jointParameters HingeJointParameters {
                  axis 0 0 1
                  anchor 0.5 0 0
                }
                device [
                  RotationalMotor {
                    name "joint2"
                  }
                ]
                endPoint Solid {
                  translation 0.75 0 0
                  children [
                    HingeJoint {
                      jointParameters HingeJointParameters {
                        axis 0 0 1
                        anchor 0.25 0 0
                      }
                      device [
                        RotationalMotor {
                          name "joint3"
                        }
                      ]
                      endPoint Solid {
                        translation 0.5 0 0
                        children [
                          Shape {
                            appearance PBRAppearance {
                              baseColor 0 0 0
                            }
                            geometry Box {
                              size 0.5 0.1 0.1
                            }
                          }
                        ]
                      }
                    }
                    Shape {
                      appearance PBRAppearance {
                        metalness 0
                      }
                      geometry Box {
                        size 0.5 0.1 0.1
                      }
                    }
                  ]
                  name "solid(1)"
                }
              }
            ]
          }
        }
      ]
    }
  ]
  name "3joints"
  controller "PmpMain_3JointsPlanar3"
  supervisor TRUE
}
DEF Ball Ball {
  translation 1.30713 -0.535183 0.03
  color 1 0 0.0156863
  mass -1
}
