#VRML_SIM R2023a utf8

EXTERNPROTO "https://raw.githubusercontent.com/cyberbotics/webots/R2023a/projects/objects/backgrounds/protos/TexturedBackground.proto"
EXTERNPROTO "https://raw.githubusercontent.com/cyberbotics/webots/R2023a/projects/objects/backgrounds/protos/TexturedBackgroundLight.proto"
EXTERNPROTO "https://raw.githubusercontent.com/cyberbotics/webots/R2023a/projects/objects/floors/protos/RectangleArena.proto"
EXTERNPROTO "../protos/Ball.proto"

WorldInfo {
}
Viewpoint {
  orientation 0.35011801338544335 -0.14422197296574737 -0.9255362765537057 3.870063114945821
  position 5.849395254897164 -4.704207784339975 6.528886297240776
}
TexturedBackground {
}
TexturedBackgroundLight {
}
RectangleArena {
  translation 0.26028 0.368433 -8.54872e-15
  floorSize 5 5
}
Robot {
  children [
    Solid {
      children [
        HingeJoint {
          jointParameters HingeJointParameters {
            axis 0 0 1
            anchor -0.5 0 0
          }
          device [
            RotationalMotor {
              name "joint1"
              minPosition -5
              maxPosition 5
            }
          ]
          endPoint Solid {
            children [
              Solid {
                children [
                  Shape {
                    appearance PBRAppearance {
                    }
                    geometry Box {
                      size 1 0.1 0.1
                    }
                  }
                ]
              }
              HingeJoint {
                jointParameters HingeJointParameters {
                  axis 0 0 1
                  anchor 0.5 0 0
                }
                device [
                  RotationalMotor {
                    name "joint2"
                  }
                ]
                endPoint Solid {
                  translation 1 0 0
                  children [
                    HingeJoint {
                      jointParameters HingeJointParameters {
                        axis 0 0 1
                        anchor 0.5 0 0
                      }
                      device [
                        RotationalMotor {
                          name "joint3"
                        }
                      ]
                      endPoint Solid {
                        translation 1 0 0
                        children [
                          Shape {
                            appearance PBRAppearance {
                              baseColor 0 0 0
                            }
                            geometry Box {
                              size 1 0.1 0.1
                            }
                          }
                        ]
                      }
                    }
                    Shape {
                      appearance PBRAppearance {
                        metalness 0
                      }
                      geometry Box {
                        size 1 0.1 0.1
                      }
                    }
                  ]
                  name "solid(1)"
                }
              }
            ]
          }
        }
      ]
    }
  ]
  name "2joints"
  controller "PmpMain"
  supervisor TRUE
}
DEF Ball Ball {
  translation 1.24565 -0.8866 0.03
}
Robot {
  translation 0 -2 0
  children [
    Solid {
      children [
        HingeJoint {
          jointParameters HingeJointParameters {
            axis 0 0 1
          }
          device [
            RotationalMotor {
              name "joint1"
            }
          ]
          endPoint Solid {
            children [
              Shape {
                appearance PBRAppearance {
                }
                geometry Box {
                  size 1 0.1 0.1
                }
              }
            ]
          }
        }
      ]
    }
    Solid {
      translation 1 0 0
      children [
        HingeJoint {
          jointParameters HingeJointParameters {
            axis 0 0 1
            anchor -0.5 0 0
          }
          device [
            RotationalMotor {
              name "joint2"
            }
          ]
          endPoint Solid {
            children [
              Shape {
                appearance PBRAppearance {
                  metalness 0
                }
                geometry Box {
                  size 1 0.1 0.1
                }
              }
            ]
          }
        }
      ]
      name "solid(1)"
    }
  ]
  name "robot_3"
  controller "<none>"
}
